Traceback (most recent call last):
  File "/Users/gaurav/miniforge3/envs/CS6910_Assignment/lib/python3.12/site-packages/wandb/sdk/wandb_config.py", line 162, in __getattr__
    return self.__getitem__(key)
           ^^^^^^^^^^^^^^^^^^^^^
  File "/Users/gaurav/miniforge3/envs/CS6910_Assignment/lib/python3.12/site-packages/wandb/sdk/wandb_config.py", line 130, in __getitem__
    return self._items[key]
           ~~~~~~~~~~~^^^^^
KeyError: 'data_augmentation'
The above exception was the direct cause of the following exception:
Traceback (most recent call last):
  File "/var/folders/3m/7slbgqtx4rlff38t_2cx53700000gp/T/ipykernel_64763/2877584091.py", line 46, in main
    run_name = "aug_" + str(config.data_augmentation) + "_bs_" + str(config.batch_size) + "_norm_" + str(config.batch_norm) + "_dropout_" + str(config.dropout) + "_fc_" + str(config.dense_size) + "_nfilters_" + str(config.num_filters) +"_ac_" + config.activation_function + "_fmul_" + str(config.filter_multiplier)
                            ^^^^^^^^^^^^^^^^^^^^^^^^
  File "/Users/gaurav/miniforge3/envs/CS6910_Assignment/lib/python3.12/site-packages/wandb/sdk/wandb_config.py", line 164, in __getattr__
    raise AttributeError(
AttributeError: <class 'wandb.sdk.wandb_config.Config'> object has no attribute 'data_augmentation'