Traceback (most recent call last):
  File "/Users/gaurav/miniforge3/envs/CS6910_Assignment/lib/python3.12/site-packages/wandb/sdk/wandb_config.py", line 162, in __getattr__
    return self.__getitem__(key)
           ^^^^^^^^^^^^^^^^^^^^^
  File "/Users/gaurav/miniforge3/envs/CS6910_Assignment/lib/python3.12/site-packages/wandb/sdk/wandb_config.py", line 130, in __getitem__
    return self._items[key]
           ~~~~~~~~~~~^^^^^
KeyError: 'filter_size'
The above exception was the direct cause of the following exception:
Traceback (most recent call last):
  File "/var/folders/3m/7slbgqtx4rlff38t_2cx53700000gp/T/ipykernel_80948/1859745293.py", line 73, in train
    filter_sizes.append(config.filter_size)
                        ^^^^^^^^^^^^^^^^^^
  File "/Users/gaurav/miniforge3/envs/CS6910_Assignment/lib/python3.12/site-packages/wandb/sdk/wandb_config.py", line 164, in __getattr__
    raise AttributeError(
AttributeError: <class 'wandb.sdk.wandb_config.Config'> object has no attribute 'filter_size'
Train:  250
Val:  63
Test:  63